Workbook

Sheet How to use
B2: Chain State level grid
B3: Mark where things go on the Map sheet; I read it and build the level in Godot.
B5: Settings (yellow cells are yours to change)
B6: Metres per square | C6: 10 | D6: Every square on the Map is this many metres across. 10 m suits islands 100-400 m wide.
B7: Level name | C7: My level | D7: What it's called on the level select.
B8: Ground height (m) | C8: 0 | D8: Height of the main island's surface. Heights you write elsewhere are relative to this.
B11: Steps
B12: 1. On the Map sheet, North is up. The orange square marks the centre (0, 0); edge labels show metres from it.
B13: 2. Type a code from the Legend sheet into each square (one code per square). Paint island areas with I.
B14: 3. Anything off the ground, or that needs a size or facing: add a row on the Details sheet (grid ref, height, size, facing).
B15: 4. Short heights can go straight in the square too: A 25 = an anchor 25 m up; I -10 = island 10 m below the main one.
B16: 5. Doors and facing: add N, E, S or W after the code, e.g. H S = house with its door facing south.
B17: 6. Send me the file (or a screenshot). I build it and send a top-down screenshot back to compare before going further.
B18: See the Example sheet: the Hamlet, drawn on this grid.

Sheet Legend
B2: Code | C2: What | D2: Notes (write extra info on the Details sheet)
B3: Ground
B4: I | C4: Island ground | D4: Paint every square of an island. Add a height for islands above/below the main one.
B5: . | C5: Road / path | D5: Cobbles in a city, dirt in a village.
B6: ~ | C6: Void (no ground) | D6: Optional: leave squares empty for the same thing.
B7: Buildings
B8: H | C8: House | D8: Add N/E/S/W for the door's side.
B9: B | C9: Big building (inn, guild hall) | D9: Size on the Details sheet.
B10: C | C10: City terrace (5 storeys) | D10: Paint a whole block; I fill it wall to wall.
B11: T | C11: Grapple tower | D11: 130 m stone tower with hook beams. Height on the Details sheet to change it.
B12: L | C12: Landmark (chapel, statue, fountain) | D12: Describe it on the Details sheet.
B13: Traversal
B14: A | C14: Grapple anchor | D14: Write its height: A 25 = 25 m up.
B15: P | C15: Landing pad / ledge | D15: Solid, not grapple-able. Height if raised.
B16: Characters
B17: S | C17: Player start | D17: One per level. Add a facing letter.
B18: N | C18: NPC | D18: Name and dialogue idea on the Details sheet.
B19: E | C19: Clue / evidence | D19: Which magic school, and what it is, on the Details sheet.
B20: Enemies
B21: W | C21: Wizard (ground) | D21: 3 wraps; throws you back.
B22: R | C22: Apprentice (flying) | D22: Patrols a wide circle round this spot. Height on the Details sheet.
B23: X | C23: Cherub (boss) | D23: Height and which way it faces.
B24: Dressing
B25: ^ | C25: Tree | D25: Several ^ = a wood.
B26: o | C26: Props (barrels, crates, carts) | D26: Free-form: I scatter a few.
B27: Your own
B28: ? | C28: Anything else | D28: Invent a code, explain it on the Details sheet.

Sheet Map
A1: N ↑ | B1: Map: type codes into the squares (see Legend)
A2: m | B2: =(COLUMN()-22)*'How to use'!$C$6 -> -200 | C2: =(COLUMN()-22)*'How to use'!$C$6 -> -190 | D2: =(COLUMN()-22)*'How to use'!$C$6 -> -180 | E2: =(COLUMN()-22)*'How to use'!$C$6 -> -170 | F2: =(COLUMN()-22)*'How to use'!$C$6 -> -160 | G2: =(COLUMN()-22)*'How to use'!$C$6 -> -150 | H2: =(COLUMN()-22)*'How to use'!$C$6 -> -140 | I2: =(COLUMN()-22)*'How to use'!$C$6 -> -130 | ... AP2: =(COLUMN()-22)*'How to use'!$C$6 -> 200
A3: =(ROW()-23)*'How to use'!$C$6 -> -200
A4: =(ROW()-23)*'How to use'!$C$6 -> -190
A5: =(ROW()-23)*'How to use'!$C$6 -> -180
A6: =(ROW()-23)*'How to use'!$C$6 -> -170
A7: =(ROW()-23)*'How to use'!$C$6 -> -160
A8: =(ROW()-23)*'How to use'!$C$6 -> -150
A9: =(ROW()-23)*'How to use'!$C$6 -> -140
A10: =(ROW()-23)*'How to use'!$C$6 -> -130
A11: =(ROW()-23)*'How to use'!$C$6 -> -120
A12: =(ROW()-23)*'How to use'!$C$6 -> -110
A13: =(ROW()-23)*'How to use'!$C$6 -> -100
A14: =(ROW()-23)*'How to use'!$C$6 -> -90
... A43: =(ROW()-23)*'How to use'!$C$6 -> 200
B45: North is up. Labels are metres from the centre (orange): east +, west -, south + (down), north - (up).

Sheet Example
A1: N ↑ | B1: Example: the Hamlet (10 m per square), as built in the game
A2: m | B2: =(COLUMN()-22)*'How to use'!$C$6 -> -200 | C2: =(COLUMN()-22)*'How to use'!$C$6 -> -190 | D2: =(COLUMN()-22)*'How to use'!$C$6 -> -180 | E2: =(COLUMN()-22)*'How to use'!$C$6 -> -170 | F2: =(COLUMN()-22)*'How to use'!$C$6 -> -160 | G2: =(COLUMN()-22)*'How to use'!$C$6 -> -150 | H2: =(COLUMN()-22)*'How to use'!$C$6 -> -140 | I2: =(COLUMN()-22)*'How to use'!$C$6 -> -130 | ... AP2: =(COLUMN()-22)*'How to use'!$C$6 -> 200
A3: =(ROW()-23)*'How to use'!$C$6 -> -200
A4: =(ROW()-23)*'How to use'!$C$6 -> -190
A5: =(ROW()-23)*'How to use'!$C$6 -> -180
A6: =(ROW()-23)*'How to use'!$C$6 -> -170
A7: =(ROW()-23)*'How to use'!$C$6 -> -160
A8: =(ROW()-23)*'How to use'!$C$6 -> -150
A9: =(ROW()-23)*'How to use'!$C$6 -> -140
A10: =(ROW()-23)*'How to use'!$C$6 -> -130
A11: =(ROW()-23)*'How to use'!$C$6 -> -120
A12: =(ROW()-23)*'How to use'!$C$6 -> -110
A13: =(ROW()-23)*'How to use'!$C$6 -> -100
A14: =(ROW()-23)*'How to use'!$C$6 -> -90
... A16: =(ROW()-23)*'How to use'!$C$6 -> -70
A17: =(ROW()-23)*'How to use'!$C$6 -> -60 | T17: I | U17: I | V17: I | W17: I | X17: I
A18: =(ROW()-23)*'How to use'!$C$6 -> -50 | S18: I | T18: I | U18: I | V18: L | W18: I | X18: I | Y18: I
A19: =(ROW()-23)*'How to use'!$C$6 -> -40 | R19: I | S19: I | T19: I | U19: I | V19: I | W19: I | X19: I | Y19: I | Z19: E
A20: =(ROW()-23)*'How to use'!$C$6 -> -30 | Q20: I | R20: I | S20: I | T20: I | U20: I | V20: . | W20: I | X20: I | Y20: E | Z20: I | AA20: I
A21: =(ROW()-23)*'How to use'!$C$6 -> -20 | P21: I | Q21: I | R21: I | S21: I | T21: I | U21: I | V21: . | W21: I | X21: I | Y21: H S | Z21: I | AA21: I | AB21: I
A22: =(ROW()-23)*'How to use'!$C$6 -> -10 | P22: I | Q22: ^ | R22: I | S22: H S | T22: I | U22: I | V22: . | W22: A 12 | X22: I | Y22: E | Z22: I | AA22: I | AB22: I
A23: =(ROW()-23)*'How to use'!$C$6 -> 0 | P23: I | Q23: . | R23: . | S23: . | T23: . | U23: . | V23: L | W23: . | X23: . | Y23: . | Z23: N | AA23: . | AB23: I
A24: =(ROW()-23)*'How to use'!$C$6 -> 10 | P24: I | Q24: I | R24: H N | S24: I | T24: I | U24: N | V24: . | W24: I | X24: I | Y24: I | Z24: B N | AA24: I | AB24: I
A25: =(ROW()-23)*'How to use'!$C$6 -> 20 | P25: I | Q25: I | R25: I | S25: I | T25: I | U25: I | V25: . | W25: I | X25: I | Y25: I | Z25: I | AA25: I | AB25: I
A26: =(ROW()-23)*'How to use'!$C$6 -> 30 | Q26: I | R26: ^ | S26: I | T26: H E | U26: I | V26: . | W26: I | X26: H W | Y26: I | Z26: I | AA26: I
A27: =(ROW()-23)*'How to use'!$C$6 -> 40 | R27: A 15 | S27: I | T27: I | U27: I | V27: . | W27: I | X27: I | Y27: I | Z27: I | AA27: ^
A28: =(ROW()-23)*'How to use'!$C$6 -> 50 | S28: I | T28: I | U28: I | V28: S N | W28: I | X28: I | Y28: I
A29: =(ROW()-23)*'How to use'!$C$6 -> 60 | T29: I | U29: I | V29: I | W29: I | X29: I
A30: =(ROW()-23)*'How to use'!$C$6 -> 70
A31: =(ROW()-23)*'How to use'!$C$6 -> 80
A32: =(ROW()-23)*'How to use'!$C$6 -> 90
A33: =(ROW()-23)*'How to use'!$C$6 -> 100
A34: =(ROW()-23)*'How to use'!$C$6 -> 110
A35: =(ROW()-23)*'How to use'!$C$6 -> 120
A36: =(ROW()-23)*'How to use'!$C$6 -> 130
A37: =(ROW()-23)*'How to use'!$C$6 -> 140
A38: =(ROW()-23)*'How to use'!$C$6 -> 150
A39: =(ROW()-23)*'How to use'!$C$6 -> 160
A40: =(ROW()-23)*'How to use'!$C$6 -> 170
A41: =(ROW()-23)*'How to use'!$C$6 -> 180
...

Sheet Details
B2: Code | C2: Grid ref (e.g. V23) | D2: Height (m) | E2: Size | F2: Facing | G2: Name / description
B3: A | C3: W21 | D3: 12 | G3: Example row: signpost anchor in the square, 12 m up
B62: Row 3 is an example (grey). Your rows start at row 4, in blue.
